Tests and Results Summary
*******************************************************************************************
Ran 3 Types of Tests (All for QR-Toolbox ver. 1.1, with logitech webcam on PowerPoint slideshow)
 1. Type 1 (Local Version) - Ran from 9:45am 2/19 to 10:25am 2/21 - PASS
 2. Type 2 (Local Version, looking to recreate generation of fake codes) - Ran from 4:40pm 2/21/20 to 7:28am 2/24/20 - PASS
 3. Type 3 (SharePoint Version) - Ran this test 6 times, all resulted in an error - FAIL
  - Test #1: 11:34am to 1:32pm 2/21/20 - FAIL - TimeoutError [WinError 10060] - 4sec interval
  - Test #2: 7:29am to 8:24am 2/24/20 - FAIL - TimeoutError [WinError 10060] - 4sec interval?
  - Test #3: 10:33am to 10:44am 2/24/20 - FAIL - HTTPError: 503 Server Error - 4sec interval?
  - Test #4: 10:51am to 11:07am 2/24/20 - FAIL - TimeoutError [WinError 10060] - 4sec interval?
  - Test #5: 11:12am to 2:58pm 2/24/20 - FAIL - TimeoutError [WinError 10060] - 10 or 9.5sec interval
  - Test #6: 3:04pm to 3:08pm 2/25/20 - FAIL - TimeoutError [WinError 10060] - 1.5sec interval
My conclusion from these tests is that the error is not caused by the client/local side,
but rather that at a certain point, the server either becomes overwhelmed by the number of requests
that are sent to it, or that it only allows so much load from one source, and so if the client
exceeds that limit, it denies the connection
(either can be concluded from: when a smaller interval was used, the error occurs faster)
However, I think the second case is likelier as I expect EPA servers to be more robust and
able to handle loads.
*******************************************************************************************
*******************************************************************************************

During Testing of QR Reader ver. SharePoint 2/21 (11:34 am to 1:32 pm) - Occurred 1:32 pm
********************************************************************************

Traceback (most recent call last):
  File "C:\Users\mkarimi\AppData\Local\Programs\Python\Python37\lib\site-packages\urllib3\connectionpool.py", line 672, in urlopen
    chunked=chunked,
  File "C:\Users\mkarimi\AppData\Local\Programs\Python\Python37\lib\site-packages\urllib3\connectionpool.py", line 376, in _make_request
    self._validate_conn(conn)
  File "C:\Users\mkarimi\AppData\Local\Programs\Python\Python37\lib\site-packages\urllib3\connectionpool.py", line 994, in _validate_conn
    conn.connect()
  File "C:\Users\mkarimi\AppData\Local\Programs\Python\Python37\lib\site-packages\urllib3\connection.py", line 360, in connect
    ssl_context=context,
  File "C:\Users\mkarimi\AppData\Local\Programs\Python\Python37\lib\site-packages\urllib3\util\ssl_.py", line 370, in ssl_wrap_socket
    return context.wrap_socket(sock, server_hostname=server_hostname)
  File "C:\Users\mkarimi\AppData\Local\Programs\Python\Python37\lib\ssl.py", line 423, in wrap_socket
    session=session
  File "C:\Users\mkarimi\AppData\Local\Programs\Python\Python37\lib\ssl.py", line 870, in _create
    self.do_handshake()
  File "C:\Users\mkarimi\AppData\Local\Programs\Python\Python37\lib\ssl.py", line 1139, in do_handshake
    self._sslobj.do_handshake()
TimeoutError: [WinError 10060] A connection attempt failed because the connected party did not properly respond after a period of time, or established connection failed because connected host has failed to respond

During handling of the above exception, another exception occurred:

Traceback (most recent call last):
  File "C:\Users\mkarimi\AppData\Local\Programs\Python\Python37\lib\site-packages\requests\adapters.py", line 449, in send
    timeout=timeout
  File "C:\Users\mkarimi\AppData\Local\Programs\Python\Python37\lib\site-packages\urllib3\connectionpool.py", line 720, in urlopen
    method, url, error=e, _pool=self, _stacktrace=sys.exc_info()[2]
  File "C:\Users\mkarimi\AppData\Local\Programs\Python\Python37\lib\site-packages\urllib3\util\retry.py", line 400, in increment
    raise six.reraise(type(error), error, _stacktrace)
  File "C:\Users\mkarimi\AppData\Local\Programs\Python\Python37\lib\site-packages\urllib3\packages\six.py", line 734, in reraise
    raise value.with_traceback(tb)
  File "C:\Users\mkarimi\AppData\Local\Programs\Python\Python37\lib\site-packages\urllib3\connectionpool.py", line 672, in urlopen
    chunked=chunked,
  File "C:\Users\mkarimi\AppData\Local\Programs\Python\Python37\lib\site-packages\urllib3\connectionpool.py", line 376, in _make_request
    self._validate_conn(conn)
  File "C:\Users\mkarimi\AppData\Local\Programs\Python\Python37\lib\site-packages\urllib3\connectionpool.py", line 994, in _validate_conn
    conn.connect()
  File "C:\Users\mkarimi\AppData\Local\Programs\Python\Python37\lib\site-packages\urllib3\connection.py", line 360, in connect
    ssl_context=context,
  File "C:\Users\mkarimi\AppData\Local\Programs\Python\Python37\lib\site-packages\urllib3\util\ssl_.py", line 370, in ssl_wrap_socket
    return context.wrap_socket(sock, server_hostname=server_hostname)
  File "C:\Users\mkarimi\AppData\Local\Programs\Python\Python37\lib\ssl.py", line 423, in wrap_socket
    session=session
  File "C:\Users\mkarimi\AppData\Local\Programs\Python\Python37\lib\ssl.py", line 870, in _create
    self.do_handshake()
  File "C:\Users\mkarimi\AppData\Local\Programs\Python\Python37\lib\ssl.py", line 1139, in do_handshake
    self._sslobj.do_handshake()
urllib3.exceptions.ProtocolError: ('Connection aborted.', TimeoutError(10060, 'A connection attempt failed because the connected party did not properly respond after a period of time, or established connection failed because connected host has failed to respond', None, 10060, None))

During handling of the above exception, another exception occurred:

Traceback (most recent call last):
  File "QR-Toolbox.py", line 773, in <module>
    video()
  File "QR-Toolbox.py", line 252, in video
    create_list_item(ctx, contentstr2)
  File "QR-Toolbox.py", line 414, in create_list_item
    context.execute_query()
  File "C:\Users\mkarimi\AppData\Local\Programs\Python\Python37\lib\site-packages\office365\runtime\client_runtime_context.py", line 38, in execute_query
    self.pending_request.execute_query()
  File "C:\Users\mkarimi\AppData\Local\Programs\Python\Python37\lib\site-packages\office365\runtime\client_request.py", line 28, in execute_query
    return self.execute_pending_queries()
  File "C:\Users\mkarimi\AppData\Local\Programs\Python\Python37\lib\site-packages\office365\runtime\client_request.py", line 34, in execute_pending_queries
    response = self.execute_request_direct(request)
  File "C:\Users\mkarimi\AppData\Local\Programs\Python\Python37\lib\site-packages\office365\runtime\client_request.py", line 124, in execute_request_direct
    auth=request_options.auth)
  File "C:\Users\mkarimi\AppData\Local\Programs\Python\Python37\lib\site-packages\requests\api.py", line 116, in post
    return request('post', url, data=data, json=json, **kwargs)
  File "C:\Users\mkarimi\AppData\Local\Programs\Python\Python37\lib\site-packages\requests\api.py", line 60, in request
    return session.request(method=method, url=url, **kwargs)
  File "C:\Users\mkarimi\AppData\Local\Programs\Python\Python37\lib\site-packages\requests\sessions.py", line 533, in request
    resp = self.send(prep, **send_kwargs)
  File "C:\Users\mkarimi\AppData\Local\Programs\Python\Python37\lib\site-packages\requests\sessions.py", line 646, in send
    r = adapter.send(request, **kwargs)
  File "C:\Users\mkarimi\AppData\Local\Programs\Python\Python37\lib\site-packages\requests\adapters.py", line 498, in send
    raise ConnectionError(err, request=request)
requests.exceptions.ConnectionError: ('Connection aborted.', TimeoutError(10060, 'A connection attempt failed because the connected party did not properly respond after a period of time, or established connection failed because connected host has failed to respond', None, 10060, None))

********************************************************************************
During Testing of QR Reader ver. SharePoint 2/24 (7:29 am to 8:24 am) - Occurred 8:24 am
********************************************************************************

Traceback (most recent call last):
  File "C:\Users\mkarimi\AppData\Local\Programs\Python\Python37\lib\site-packages\urllib3\connection.py", line 157, in _new_conn
    (self._dns_host, self.port), self.timeout, **extra_kw
  File "C:\Users\mkarimi\AppData\Local\Programs\Python\Python37\lib\site-packages\urllib3\util\connection.py", line 84, in create_connection
    raise err
  File "C:\Users\mkarimi\AppData\Local\Programs\Python\Python37\lib\site-packages\urllib3\util\connection.py", line 74, in create_connection
    sock.connect(sa)
TimeoutError: [WinError 10060] A connection attempt failed because the connected party did not properly respond after a period of time, or established connection failed because connected host has failed to respond

During handling of the above exception, another exception occurred:

Traceback (most recent call last):
  File "C:\Users\mkarimi\AppData\Local\Programs\Python\Python37\lib\site-packages\urllib3\connectionpool.py", line 672, in urlopen
    chunked=chunked,
  File "C:\Users\mkarimi\AppData\Local\Programs\Python\Python37\lib\site-packages\urllib3\connectionpool.py", line 376, in _make_request
    self._validate_conn(conn)
  File "C:\Users\mkarimi\AppData\Local\Programs\Python\Python37\lib\site-packages\urllib3\connectionpool.py", line 994, in _validate_conn
    conn.connect()
  File "C:\Users\mkarimi\AppData\Local\Programs\Python\Python37\lib\site-packages\urllib3\connection.py", line 300, in connect
    conn = self._new_conn()
  File "C:\Users\mkarimi\AppData\Local\Programs\Python\Python37\lib\site-packages\urllib3\connection.py", line 169, in _new_conn
    self, "Failed to establish a new connection: %s" % e
urllib3.exceptions.NewConnectionError: <urllib3.connection.VerifiedHTTPSConnection object at 0x000001601257C0C8>: Failed to establish a new connection: [WinError 10060] A connection attempt failed because the connected party did not properly respond after a period of time, or established connection failed because connected host has failed to respond

During handling of the above exception, another exception occurred:

Traceback (most recent call last):
  File "C:\Users\mkarimi\AppData\Local\Programs\Python\Python37\lib\site-packages\requests\adapters.py", line 449, in send
    timeout=timeout
  File "C:\Users\mkarimi\AppData\Local\Programs\Python\Python37\lib\site-packages\urllib3\connectionpool.py", line 720, in urlopen
    method, url, error=e, _pool=self, _stacktrace=sys.exc_info()[2]
  File "C:\Users\mkarimi\AppData\Local\Programs\Python\Python37\lib\site-packages\urllib3\util\retry.py", line 436, in increment
    raise MaxRetryError(_pool, url, error or ResponseError(cause))
urllib3.exceptions.MaxRetryError: HTTPSConnectionPool(host='usepa.sharepoint.com', port=443): Max retries exceeded with url: /sites/Emergency%20Response/EOCIncident/_api/Web/lists/GetByTitle('QR%20Timestamps')/items (Caused by NewConnectionError('<urllib3.connection.VerifiedHTTPSConnection object at 0x000001601257C0C8>: Failed to establish a new connection: [WinError 10060] A connection attempt failed because the connected party did not properly respond after a period of time, or established connection failed because connected host has failed to respond'))

During handling of the above exception, another exception occurred:

Traceback (most recent call last):
  File "QR-Toolbox.py", line 773, in <module>
    video()
  File "QR-Toolbox.py", line 252, in video
    create_list_item(ctx, contentstr2)
  File "QR-Toolbox.py", line 414, in create_list_item
    context.execute_query()
  File "C:\Users\mkarimi\AppData\Local\Programs\Python\Python37\lib\site-packages\office365\runtime\client_runtime_context.py", line 38, in execute_query
    self.pending_request.execute_query()
  File "C:\Users\mkarimi\AppData\Local\Programs\Python\Python37\lib\site-packages\office365\runtime\client_request.py", line 28, in execute_query
    return self.execute_pending_queries()
  File "C:\Users\mkarimi\AppData\Local\Programs\Python\Python37\lib\site-packages\office365\runtime\client_request.py", line 34, in execute_pending_queries
    response = self.execute_request_direct(request)
  File "C:\Users\mkarimi\AppData\Local\Programs\Python\Python37\lib\site-packages\office365\runtime\client_request.py", line 124, in execute_request_direct
    auth=request_options.auth)
  File "C:\Users\mkarimi\AppData\Local\Programs\Python\Python37\lib\site-packages\requests\api.py", line 116, in post
    return request('post', url, data=data, json=json, **kwargs)
  File "C:\Users\mkarimi\AppData\Local\Programs\Python\Python37\lib\site-packages\requests\api.py", line 60, in request
    return session.request(method=method, url=url, **kwargs)
  File "C:\Users\mkarimi\AppData\Local\Programs\Python\Python37\lib\site-packages\requests\sessions.py", line 533, in request
    resp = self.send(prep, **send_kwargs)
  File "C:\Users\mkarimi\AppData\Local\Programs\Python\Python37\lib\site-packages\requests\sessions.py", line 646, in send
    r = adapter.send(request, **kwargs)
  File "C:\Users\mkarimi\AppData\Local\Programs\Python\Python37\lib\site-packages\requests\adapters.py", line 516, in send
    raise ConnectionError(e, request=request)
requests.exceptions.ConnectionError: HTTPSConnectionPool(host='usepa.sharepoint.com', port=443): Max retries exceeded with url: /sites/Emergency%20Response/EOCIncident/_api/Web/lists/GetByTitle('QR%20Timestamps')/items (Caused by NewConnectionError('<urllib3.connection.VerifiedHTTPSConnection object at 0x000001601257C0C8>: Failed to establish a new connection: [WinError 10060] A connection attempt failed because the connected party did not properly respond after a period of time, or established connection failed because connected host has failed to respond'))

********************************************************************************
During Testing of QR Reader ver. SharePoint 2/24 (10:33 am to 10:44 am) - Occurred 10:44 am
********************************************************************************

Traceback (most recent call last):
  File "C:\Users\mkarimi\AppData\Local\Programs\Python\Python37\lib\site-packages\office365\runtime\client_request.py", line 147, in validate_response
    response.raise_for_status()
  File "C:\Users\mkarimi\AppData\Local\Programs\Python\Python37\lib\site-packages\requests\models.py", line 940, in raise_for_status
    raise HTTPError(http_error_msg, response=self)
requests.exceptions.HTTPError: 503 Server Error: Service Unavailable for url: https://usepa.sharepoint.com/sites/Emergency%20Response/EOCIncident/_api/Web/lists/GetByTitle('QR%20Timestamps')/items

During handling of the above exception, another exception occurred:

Traceback (most recent call last):
  File "QR-Toolbox.py", line 773, in <module>
    video()
  File "QR-Toolbox.py", line 252, in video
    create_list_item(ctx, contentstr2)
  File "QR-Toolbox.py", line 414, in create_list_item
    context.execute_query()
  File "C:\Users\mkarimi\AppData\Local\Programs\Python\Python37\lib\site-packages\office365\runtime\client_runtime_context.py", line 38, in execute_query
    self.pending_request.execute_query()
  File "C:\Users\mkarimi\AppData\Local\Programs\Python\Python37\lib\site-packages\office365\runtime\client_request.py", line 28, in execute_query
    return self.execute_pending_queries()
  File "C:\Users\mkarimi\AppData\Local\Programs\Python\Python37\lib\site-packages\office365\runtime\client_request.py", line 35, in execute_pending_queries
    self.process_payload_json(query, response)
  File "C:\Users\mkarimi\AppData\Local\Programs\Python\Python37\lib\site-packages\office365\runtime\client_request.py", line 46, in process_payload_json
    payload = self.process_response_json(response)
  File "C:\Users\mkarimi\AppData\Local\Programs\Python\Python37\lib\site-packages\office365\runtime\client_request.py", line 54, in process_response_json
    self.validate_response(response)
  File "C:\Users\mkarimi\AppData\Local\Programs\Python\Python37\lib\site-packages\office365\runtime\client_request.py", line 149, in validate_response
    raise ClientRequestException(*e.args, response=e.response)
office365.runtime.client_request_exception.ClientRequestException: (None, None, "503 Server Error: Service Unavailable for url: https://usepa.sharepoint.com/sites/Emergency%20Response/EOCIncident/_api/Web/lists/GetByTitle('QR%20Timestamps')/items")

********************************************************************************
During Testing of QR Reader ver. SharePoint 2/24 (10:51 am to 11:07 am) - Occurred 11:07 am
********************************************************************************

Traceback (most recent call last):
  File "C:\Users\mkarimi\AppData\Local\Programs\Python\Python37\lib\site-packages\urllib3\connection.py", line 157, in _new_conn
    (self._dns_host, self.port), self.timeout, **extra_kw
  File "C:\Users\mkarimi\AppData\Local\Programs\Python\Python37\lib\site-packages\urllib3\util\connection.py", line 84, in create_connection
    raise err
  File "C:\Users\mkarimi\AppData\Local\Programs\Python\Python37\lib\site-packages\urllib3\util\connection.py", line 74, in create_connection
    sock.connect(sa)
TimeoutError: [WinError 10060] A connection attempt failed because the connected party did not properly respond after a period of time, or established connection failed because connected host has failed to respond

During handling of the above exception, another exception occurred:

Traceback (most recent call last):
  File "C:\Users\mkarimi\AppData\Local\Programs\Python\Python37\lib\site-packages\urllib3\connectionpool.py", line 672, in urlopen
    chunked=chunked,
  File "C:\Users\mkarimi\AppData\Local\Programs\Python\Python37\lib\site-packages\urllib3\connectionpool.py", line 376, in _make_request
    self._validate_conn(conn)
  File "C:\Users\mkarimi\AppData\Local\Programs\Python\Python37\lib\site-packages\urllib3\connectionpool.py", line 994, in _validate_conn
    conn.connect()
  File "C:\Users\mkarimi\AppData\Local\Programs\Python\Python37\lib\site-packages\urllib3\connection.py", line 300, in connect
    conn = self._new_conn()
  File "C:\Users\mkarimi\AppData\Local\Programs\Python\Python37\lib\site-packages\urllib3\connection.py", line 169, in _new_conn
    self, "Failed to establish a new connection: %s" % e
urllib3.exceptions.NewConnectionError: <urllib3.connection.VerifiedHTTPSConnection object at 0x000001AC92A1DB48>: Failed to establish a new connection: [WinError 10060] A connection attempt failed because the connected party did not properly respond after a period of time, or established connection failed because connected host has failed to respond

During handling of the above exception, another exception occurred:

Traceback (most recent call last):
  File "C:\Users\mkarimi\AppData\Local\Programs\Python\Python37\lib\site-packages\requests\adapters.py", line 449, in send
    timeout=timeout
  File "C:\Users\mkarimi\AppData\Local\Programs\Python\Python37\lib\site-packages\urllib3\connectionpool.py", line 720, in urlopen
    method, url, error=e, _pool=self, _stacktrace=sys.exc_info()[2]
  File "C:\Users\mkarimi\AppData\Local\Programs\Python\Python37\lib\site-packages\urllib3\util\retry.py", line 436, in increment
    raise MaxRetryError(_pool, url, error or ResponseError(cause))
urllib3.exceptions.MaxRetryError: HTTPSConnectionPool(host='usepa.sharepoint.com', port=443): Max retries exceeded with url: /sites/Emergency%20Response/EOCIncident/_api/Web/lists/GetByTitle('QR%20Timestamps')/items (Caused by NewConnectionError('<urllib3.connection.VerifiedHTTPSConnection object at 0x000001AC92A1DB48>: Failed to establish a new connection: [WinError 10060] A connection attempt failed because the connected party did not properly respond after a period of time, or established connection failed because connected host has failed to respond'))

During handling of the above exception, another exception occurred:

Traceback (most recent call last):
  File "QR-Toolbox.py", line 773, in <module>
    video()
  File "QR-Toolbox.py", line 220, in video
    create_list_item(ctx, contentstr2)
  File "QR-Toolbox.py", line 414, in create_list_item
    context.execute_query()
  File "C:\Users\mkarimi\AppData\Local\Programs\Python\Python37\lib\site-packages\office365\runtime\client_runtime_context.py", line 38, in execute_query
    self.pending_request.execute_query()
  File "C:\Users\mkarimi\AppData\Local\Programs\Python\Python37\lib\site-packages\office365\runtime\client_request.py", line 28, in execute_query
    return self.execute_pending_queries()
  File "C:\Users\mkarimi\AppData\Local\Programs\Python\Python37\lib\site-packages\office365\runtime\client_request.py", line 34, in execute_pending_queries
    response = self.execute_request_direct(request)
  File "C:\Users\mkarimi\AppData\Local\Programs\Python\Python37\lib\site-packages\office365\runtime\client_request.py", line 124, in execute_request_direct
    auth=request_options.auth)
  File "C:\Users\mkarimi\AppData\Local\Programs\Python\Python37\lib\site-packages\requests\api.py", line 116, in post
    return request('post', url, data=data, json=json, **kwargs)
  File "C:\Users\mkarimi\AppData\Local\Programs\Python\Python37\lib\site-packages\requests\api.py", line 60, in request
    return session.request(method=method, url=url, **kwargs)
  File "C:\Users\mkarimi\AppData\Local\Programs\Python\Python37\lib\site-packages\requests\sessions.py", line 533, in request
    resp = self.send(prep, **send_kwargs)
  File "C:\Users\mkarimi\AppData\Local\Programs\Python\Python37\lib\site-packages\requests\sessions.py", line 646, in send
    r = adapter.send(request, **kwargs)
  File "C:\Users\mkarimi\AppData\Local\Programs\Python\Python37\lib\site-packages\requests\adapters.py", line 516, in send
    raise ConnectionError(e, request=request)
requests.exceptions.ConnectionError: HTTPSConnectionPool(host='usepa.sharepoint.com', port=443): Max retries exceeded with url: /sites/Emergency%20Response/EOCIncident/_api/Web/lists/GetByTitle('QR%20Timestamps')/items (Caused by NewConnectionError('<urllib3.connection.VerifiedHTTPSConnection object at 0x000001AC92A1DB48>: Failed to establish a new connection: [WinError 10060] A connection attempt failed because the connected party did not properly respond after a period of time, or established connection failed because connected host has failed to respond'))

********************************************************************************
During Testing of QR Reader ver. SharePoint 2/24 (11:12 am to 2:58 pm) - Occurred 2:58 pm
********************************************************************************

Traceback (most recent call last):
  File "C:\Users\mkarimi\AppData\Local\Programs\Python\Python37\lib\site-packages\urllib3\connection.py", line 157, in _new_conn
    (self._dns_host, self.port), self.timeout, **extra_kw
  File "C:\Users\mkarimi\AppData\Local\Programs\Python\Python37\lib\site-packages\urllib3\util\connection.py", line 84, in create_connection
    raise err
  File "C:\Users\mkarimi\AppData\Local\Programs\Python\Python37\lib\site-packages\urllib3\util\connection.py", line 74, in create_connection
    sock.connect(sa)
TimeoutError: [WinError 10060] A connection attempt failed because the connected party did not properly respond after a period of time, or established connection failed because connected host has failed to respond

During handling of the above exception, another exception occurred:

Traceback (most recent call last):
  File "C:\Users\mkarimi\AppData\Local\Programs\Python\Python37\lib\site-packages\urllib3\connectionpool.py", line 672, in urlopen
    chunked=chunked,
  File "C:\Users\mkarimi\AppData\Local\Programs\Python\Python37\lib\site-packages\urllib3\connectionpool.py", line 376, in _make_request
    self._validate_conn(conn)
  File "C:\Users\mkarimi\AppData\Local\Programs\Python\Python37\lib\site-packages\urllib3\connectionpool.py", line 994, in _validate_conn
    conn.connect()
  File "C:\Users\mkarimi\AppData\Local\Programs\Python\Python37\lib\site-packages\urllib3\connection.py", line 300, in connect
    conn = self._new_conn()
  File "C:\Users\mkarimi\AppData\Local\Programs\Python\Python37\lib\site-packages\urllib3\connection.py", line 169, in _new_conn
    self, "Failed to establish a new connection: %s" % e
urllib3.exceptions.NewConnectionError: <urllib3.connection.VerifiedHTTPSConnection object at 0x000002A7FF9E7988>: Failed to establish a new connection: [WinError 10060] A connection attempt failed because the connected party did not properly respond after a period of time, or established connection failed because connected host has failed to respond

During handling of the above exception, another exception occurred:

Traceback (most recent call last):
  File "C:\Users\mkarimi\AppData\Local\Programs\Python\Python37\lib\site-packages\requests\adapters.py", line 449, in send
    timeout=timeout
  File "C:\Users\mkarimi\AppData\Local\Programs\Python\Python37\lib\site-packages\urllib3\connectionpool.py", line 720, in urlopen
    method, url, error=e, _pool=self, _stacktrace=sys.exc_info()[2]
  File "C:\Users\mkarimi\AppData\Local\Programs\Python\Python37\lib\site-packages\urllib3\util\retry.py", line 436, in increment
    raise MaxRetryError(_pool, url, error or ResponseError(cause))
urllib3.exceptions.MaxRetryError: HTTPSConnectionPool(host='usepa.sharepoint.com', port=443): Max retries exceeded with url: /sites/Emergency%20Response/EOCIncident/_api/Web/lists/GetByTitle('QR%20Timestamps')/items (Caused by NewConnectionError('<urllib3.connection.VerifiedHTTPSConnection object at 0x000002A7FF9E7988>: Failed to establish a new connection: [WinError 10060] A connection attempt failed because the connected party did not properly respond after a period of time, or established connection failed because connected host has failed to respond'))

During handling of the above exception, another exception occurred:

Traceback (most recent call last):
  File "QR-Toolbox.py", line 773, in <module>
    video()
  File "QR-Toolbox.py", line 252, in video
    create_list_item(ctx, contentstr2)
  File "QR-Toolbox.py", line 414, in create_list_item
    context.execute_query()
  File "C:\Users\mkarimi\AppData\Local\Programs\Python\Python37\lib\site-packages\office365\runtime\client_runtime_context.py", line 38, in execute_query
    self.pending_request.execute_query()
  File "C:\Users\mkarimi\AppData\Local\Programs\Python\Python37\lib\site-packages\office365\runtime\client_request.py", line 28, in execute_query
    return self.execute_pending_queries()
  File "C:\Users\mkarimi\AppData\Local\Programs\Python\Python37\lib\site-packages\office365\runtime\client_request.py", line 34, in execute_pending_queries
    response = self.execute_request_direct(request)
  File "C:\Users\mkarimi\AppData\Local\Programs\Python\Python37\lib\site-packages\office365\runtime\client_request.py", line 124, in execute_request_direct
    auth=request_options.auth)
  File "C:\Users\mkarimi\AppData\Local\Programs\Python\Python37\lib\site-packages\requests\api.py", line 116, in post
    return request('post', url, data=data, json=json, **kwargs)
  File "C:\Users\mkarimi\AppData\Local\Programs\Python\Python37\lib\site-packages\requests\api.py", line 60, in request
    return session.request(method=method, url=url, **kwargs)
  File "C:\Users\mkarimi\AppData\Local\Programs\Python\Python37\lib\site-packages\requests\sessions.py", line 533, in request
    resp = self.send(prep, **send_kwargs)
  File "C:\Users\mkarimi\AppData\Local\Programs\Python\Python37\lib\site-packages\requests\sessions.py", line 646, in send
    r = adapter.send(request, **kwargs)
  File "C:\Users\mkarimi\AppData\Local\Programs\Python\Python37\lib\site-packages\requests\adapters.py", line 516, in send
    raise ConnectionError(e, request=request)
requests.exceptions.ConnectionError: HTTPSConnectionPool(host='usepa.sharepoint.com', port=443): Max retries exceeded with url: /sites/Emergency%20Response/EOCIncident/_api/Web/lists/GetByTitle('QR%20Timestamps')/items (Caused by NewConnectionError('<urllib3.connection.VerifiedHTTPSConnection object at 0x000002A7FF9E7988>: Failed to establish a new connection: [WinError 10060] A connection attempt failed because the connected party did not properly respond after a period of time, or established connection failed because connected host has failed to respond'))

********************************************************************************
During Testing of QR Reader ver. SharePoint (1.5sec intervals) 2/25 (3:04 pm to 3:08 pm)
 - Error occurred 3:08 pm
********************************************************************************

Traceback (most recent call last):
  File "C:\Users\mkarimi\AppData\Local\Programs\Python\Python37\lib\site-packages\urllib3\connection.py", line 157, in _new_conn
    (self._dns_host, self.port), self.timeout, **extra_kw
  File "C:\Users\mkarimi\AppData\Local\Programs\Python\Python37\lib\site-packages\urllib3\util\connection.py", line 84, in create_connection
    raise err
  File "C:\Users\mkarimi\AppData\Local\Programs\Python\Python37\lib\site-packages\urllib3\util\connection.py", line 74, in create_connection
    sock.connect(sa)
TimeoutError: [WinError 10060] A connection attempt failed because the connected party did not properly respond after a period of time, or established connection failed because connected host has failed to respond

During handling of the above exception, another exception occurred:

Traceback (most recent call last):
  File "C:\Users\mkarimi\AppData\Local\Programs\Python\Python37\lib\site-packages\urllib3\connectionpool.py", line 672, in urlopen
    chunked=chunked,
  File "C:\Users\mkarimi\AppData\Local\Programs\Python\Python37\lib\site-packages\urllib3\connectionpool.py", line 376, in _make_request
    self._validate_conn(conn)
  File "C:\Users\mkarimi\AppData\Local\Programs\Python\Python37\lib\site-packages\urllib3\connectionpool.py", line 994, in _validate_conn
    conn.connect()
  File "C:\Users\mkarimi\AppData\Local\Programs\Python\Python37\lib\site-packages\urllib3\connection.py", line 300, in connect
    conn = self._new_conn()
  File "C:\Users\mkarimi\AppData\Local\Programs\Python\Python37\lib\site-packages\urllib3\connection.py", line 169, in _new_conn
    self, "Failed to establish a new connection: %s" % e
urllib3.exceptions.NewConnectionError: <urllib3.connection.VerifiedHTTPSConnection object at 0x000001D31B0CDE48>: Failed to establish a new connection: [WinError 10060] A connection attempt failed because the connected party did not properly respond after a period of time, or established connection failed because connected host has failed to respond

During handling of the above exception, another exception occurred:

Traceback (most recent call last):
  File "C:\Users\mkarimi\AppData\Local\Programs\Python\Python37\lib\site-packages\requests\adapters.py", line 449, in send
    timeout=timeout
  File "C:\Users\mkarimi\AppData\Local\Programs\Python\Python37\lib\site-packages\urllib3\connectionpool.py", line 720, in urlopen
    method, url, error=e, _pool=self, _stacktrace=sys.exc_info()[2]
  File "C:\Users\mkarimi\AppData\Local\Programs\Python\Python37\lib\site-packages\urllib3\util\retry.py", line 436, in increment
    raise MaxRetryError(_pool, url, error or ResponseError(cause))
urllib3.exceptions.MaxRetryError: HTTPSConnectionPool(host='usepa.sharepoint.com', port=443): Max retries exceeded with url: /sites/Emergency%20Response/EOCIncident/_api/Web/lists/GetByTitle('QR%20Timestamps')/items (Caused by NewConnectionError('<urllib3.connection.VerifiedHTTPSConnection object at 0x000001D31B0CDE48>: Failed to establish a new connection: [WinError 10060] A connection attempt failed because the connected party did not properly respond after a period of time, or established connection failed because connected host has failed to respond'))

During handling of the above exception, another exception occurred:

Traceback (most recent call last):
  File "QR-Toolbox.py", line 773, in <module>
    video()
  File "QR-Toolbox.py", line 220, in video
    create_list_item(ctx, contentstr2)
  File "QR-Toolbox.py", line 414, in create_list_item
    context.execute_query()
  File "C:\Users\mkarimi\AppData\Local\Programs\Python\Python37\lib\site-packages\office365\runtime\client_runtime_context.py", line 38, in execute_query
    self.pending_request.execute_query()
  File "C:\Users\mkarimi\AppData\Local\Programs\Python\Python37\lib\site-packages\office365\runtime\client_request.py", line 28, in execute_query
    return self.execute_pending_queries()
  File "C:\Users\mkarimi\AppData\Local\Programs\Python\Python37\lib\site-packages\office365\runtime\client_request.py", line 34, in execute_pending_queries
    response = self.execute_request_direct(request)
  File "C:\Users\mkarimi\AppData\Local\Programs\Python\Python37\lib\site-packages\office365\runtime\client_request.py", line 124, in execute_request_direct
    auth=request_options.auth)
  File "C:\Users\mkarimi\AppData\Local\Programs\Python\Python37\lib\site-packages\requests\api.py", line 116, in post
    return request('post', url, data=data, json=json, **kwargs)
  File "C:\Users\mkarimi\AppData\Local\Programs\Python\Python37\lib\site-packages\requests\api.py", line 60, in request
    return session.request(method=method, url=url, **kwargs)
  File "C:\Users\mkarimi\AppData\Local\Programs\Python\Python37\lib\site-packages\requests\sessions.py", line 533, in request
    resp = self.send(prep, **send_kwargs)
  File "C:\Users\mkarimi\AppData\Local\Programs\Python\Python37\lib\site-packages\requests\sessions.py", line 646, in send
    r = adapter.send(request, **kwargs)
  File "C:\Users\mkarimi\AppData\Local\Programs\Python\Python37\lib\site-packages\requests\adapters.py", line 516, in send
    raise ConnectionError(e, request=request)
requests.exceptions.ConnectionError: HTTPSConnectionPool(host='usepa.sharepoint.com', port=443): Max retries exceeded with url: /sites/Emergency%20Response/EOCIncident/_api/Web/lists/GetByTitle('QR%20Timestamps')/items (Caused by NewConnectionError('<urllib3.connection.VerifiedHTTPSConnection object at 0x000001D31B0CDE48>: Failed to establish a new connection: [WinError 10060] A connection attempt failed because the connected party did not properly respond after a period of time, or established connection failed because connected host has failed to respond'))